Workbook

Sheet 퇴사자
AJ1: date. | AK1: =TODAY() -> 46114
A2: 구분 | B2: 사번 | C2: 구분 | D2: 이름 | E2: 직책 | G2: 소속 | H2: 부서 | I2: 주민등록번호 | J2: 입사일 | K2: 최근승진 | L2: 퇴사일 | M2: 학력 | N2: 학교 | O2: 전공 | Q2: 학위 | S2: 자격증1 | T2: 합격일 | U2: 자격증2 | V2: 합격일 | W2: 자격증3 | X2: 합격일 | Y2: 경력등급 | Z2: 경력증 | AA2: 취득일 | AB2: 자격증기준등급 | AC2: 전직장경력합계 | AD2: 전직장경력년수 | AE2: 근속합계 | AF2: 근속년수 | AG2: 총경력합 | AH2: 총경력년수 | AI2: 집주소 | AJ2: 핸드폰 | AK2: e-mail
A3: 2 | D3: 김정태 | E3: 차장 | G3: 플랫폼 사업본부 | J3: 40742 | K3: 0 | L3: 40928 | Y3: 중 | AC3: =+#REF!+#REF!+#REF!+#REF!+#REF!+#REF!+#REF! -> #REF! | AD3: 0년 0개월 | AE3: 17.5 | AF3: 1년 5개월 | AG3: 17.5 | AH3: 1년 5개월 | AI3: 경기도 광명시 하안2동 하안주공아파트 312동 504호 | AJ3: 010-7204-2885 | AK3: njlee@in-soft.co.kr
A4: 3 | D4: 박진형 | E4: 대리 | G4: 플랫폼 사업본부 | J4: 40513 | K4: 0 | L4: 40939 | Y4: 중 | AC4: =+#REF!+#REF!+#REF!+#REF!+#REF!+#REF!+#REF! -> #REF! | AD4: 0년 0개월 | AE4: 25.133333 | AF4: 2년 1개월 | AG4: 25.133333 | AH4: 2년 1개월 | AI4: 서울시 송파구 문정동 121-13 지영하우스 302호 | AJ4: 010-6365-7859 | AK4: yyyoon@in-soft.co.kr
A5: 4 | D5: 김제연 | E5: 사원 | G5: 클라우드 사업본부 | J5: 40381 | K5: 2011년 7월 | L5: 40939 | Y5: 고 | AC5: =+#REF!+#REF!+#REF!+#REF!+#REF!+#REF!+#REF! -> #REF! | AD5: 0년 0개월 | AE5: 29.533333 | AF5: 2년 5개월 | AG5: 29.533333 | AH5: 2년 5개월 | AI5: 경기도 남양주시 화도읍 녹촌리 녹촌두산위브아파트 104-1104 | AJ5: 010-3718-9184 | AK5: yihong@in-soft.co.kr
A6: 5 | D6: 신동창 | E6: 대리 | G6: Ubicom 연구소 | J6: 40513 | K6: 0 | L6: 40968 | Y6: 초 | AC6: =+#REF!+#REF!+#REF!+#REF!+#REF!+#REF!+#REF! -> #REF! | AD6: 0년 0개월 | AE6: 25.133333 | AF6: 2년 1개월 | AG6: 25.133333 | AH6: 2년 1개월 | AI6: 서울시 도봉구 방학동 649-39번지 5층 | AJ6: 010-6864-0073 | AK6: shsung@in-soft.co.kr
A7: 6 | D7: 송정윤 | E7: 사원 | G7: 플랫폼 사업본부 | J7: 40568 | K7: 0 | L7: 40983 | Y7: 초 | AC7: =+#REF!+#REF!+#REF!+#REF!+#REF!+#REF!+#REF! -> #REF! | AD7: 0년 0개월 | AE7: 23.3 | AF7: 1년 11개월 | AG7: 23.3 | AH7: 1년 11개월 | AI7: 경기도 하남시 신장동 백송한신아파트 103동 1511호 | AJ7: 010-5011-7269 | AK7: smlee@in-soft.co.kr
A8: 7 | D8: 송보근 | E8: 차장 | G8: CSBU | J8: 38504 | K8: 2012년 7월 | L8: 40999 | Y8: 고 | AC8: =+#REF!+#REF!+#REF!+#REF!+#REF!+#REF!+#REF! -> #REF! | AD8: 0년 0개월 | AE8: 92.1 | AF8: 7년 8개월 | AG8: 92.1 | AH8: 7년 8개월 | AI8: 경기도 의정부시 신곡1동 풍림아파트 603동 802호 | AJ8: 010-6247-3959 | AK8: jhcho@in-soft.co.kr
A9: 8 | D9: 박선용 | E9: 대리 | G9: CSBU | J9: 39356 | K9: 0 | L9: 40999 | Y9: 초 | AC9: =+#REF!+#REF!+#REF!+#REF!+#REF!+#REF!+#REF! -> #REF! | AD9: 0년 0개월 | AE9: 63.7 | AF9: 5년 3개월 | AG9: 63.7 | AH9: 5년 3개월 | AI9: 경기도 김포시 통진읍 마송리 마송휴먼시아 매수리마을 902-803 | AJ9: 010-6410-5450 | AK9: mhlee@in-soft.co.kr
A10: 9 | D10: 이승준 | E10: 과장 | G10: CSBU | J10: 39755 | K10: 0 | L10: 40999 | Y10: 0 | AC10: =+#REF!+#REF!+#REF!+#REF!+#REF!+#REF!+#REF! -> #REF! | AD10: 0년 0개월 | AE10: 50.4 | AF10: 4년 2개월 | AG10: 50.4 | AH10: 4년 2개월 | AI10: 경기도 부천시 소사구 송내동 327-2 성호아파트 102동 106호 | AJ10: 010-3244-2434
A11: 10 | D11: 이정환 | E11: 대리 | G11: CSBU | J11: 40098 | K11: 0 | L11: 40999 | Y11: 초 | AC11: =+#REF!+#REF!+#REF!+#REF!+#REF!+#REF!+#REF! -> #REF! | AD11: 0년 0개월 | AE11: 38.966667 | AF11: 3년 2개월 | AG11: 38.966667 | AH11: 3년 2개월 | AI11: 경기도 평택시 청북면 어연리 262-1 | AJ11: 010-6298-3217
A12: 11 | D12: 정성수 | E12: 대리 | G12: 플랫폼 사업본부 | J12: 40168 | L12: 41005 | AC12: =+#REF!+#REF!+#REF!+#REF!+#REF!+#REF!+#REF! -> #REF! | AD12: 0년 0개월 | AE12: 36.633333 | AF12: 3년 0개월
A13: 12 | D13: 전영세 | E13: 대리 | G13: 플랫폼 사업본부 | J13: 39479 | L13: 41005 | AC13: =+#REF!+#REF!+#REF!+#REF!+#REF!+#REF!+#REF! -> #REF! | AD13: 0년 0개월 | AE13: 59.6 | AF13: 4년 11개월
A14: 13 | D14: 강복구 | E14: 대리 | G14: 플랫폼 사업본부 | J14: 39574 | L14: 41009 | AC14: =+#REF!+#REF!+#REF!+#REF!+#REF!+#REF!+#REF! -> #REF! | AD14: 0년 0개월 | AE14: 56.433333 | AF14: 4년 8개월
A15: 14 | D15: 최기범 | E15: 사원 | G15: 클라우드 사업본부 | J15: 40588 | L15: 41026 | AC15: =+#REF!+#REF!+#REF!+#REF!+#REF!+#REF!+#REF! -> #REF! | AD15: 0년 0개월 | AE15: 22.633333 | AF15: 1년 10개월
A16: 15 | D16: 정준영 | E16: 대리 | G16: 플랫폼 사업본부 | J16: 40266 | L16: 41029 | AC16: =+#REF!+#REF!+#REF!+#REF!+#REF!+#REF!+#REF! -> #REF! | AD16: 0년 0개월 | AE16: 33.366667 | AF16: 2년 9개월
A17: 16 | D17: 남태규 | E17: 차장 | G17: 솔루션 사업부 | J17: 40391 | L17: 41029 | AC17: =+#REF!+#REF!+#REF!+#REF!+#REF!+#REF!+#REF! -> #REF! | AD17: 0년 0개월 | AE17: 29.2 | AF17: 2년 5개월
A18: 17 | D18: 임옥하 | E18: 대리 | G18: 플랫폼 사업본부 | J18: 40360 | L18: 41029 | AC18: =+#REF!+#REF!+#REF!+#REF!+#REF!+#REF!+#REF! -> #REF! | AD18: 0년 0개월 | AE18: 30.233333 | AF18: 2년 6개월
A19: 18 | D19: 변기웅 | E19: 과장 | G19: 영업팀 | J19: 40763 | L19: 41029 | AC19: =+#REF!+#REF!+#REF!+#REF!+#REF!+#REF!+#REF! -> #REF! | AD19: 0년 0개월 | AE19: 16.8 | AF19: 1년 4개월
A20: 1 | D20: 윤지선 | E20: 사원 | G20: PS팀 | J20: 39694 | K20: 0 | L20: 40921 | Y20: 초 | AC20: =+#REF!+#REF!+#REF!+#REF!+#REF!+#REF!+#REF! -> #REF! | AD20: 0년 0개월 | AE20: 52.433333 | AF20: 4년 4개월 | AG20: 52.433333 | AH20: 4년 4개월 | AI20: 경기도 고양시 일산동구 중산동 25-12 | AJ20: 010-2515-0116 | AK20: dklee@in-soft.co.kr
A21: 19 | D21: 박준희 | E21: 차장 | G21: 플랫폼 사업본부 | J21: 40910 | L21: 41033 | AC21: =+#REF!+#REF!+#REF!+#REF!+#REF!+#REF!+#REF! -> #REF! | AD21: 0년 0개월 | AE21: 11.9 | AF21: 0년 11개월
A22: 20 | D22: 김민석 | E22: 사원 | G22: 클라우드 사업본부 | J22: 40589 | L22: 41038 | AC22: =+#REF!+#REF!+#REF!+#REF!+#REF!+#REF!+#REF! -> #REF! | AD22: 0년 0개월 | AE22: 22.6 | AF22: 1년 10개월
A23: 21 | D23: 장현우 | E23: 과장 | G23: 클라우드 사업본부 | J23: 41024 | L23: 41060 | AC23: =+#REF!+#REF!+#REF!+#REF!+#REF!+#REF!+#REF! -> #REF! | AD23: 0년 0개월 | AE23: 8.1 | AF23: 0년 8개월
A24: 22 | D24: 이왕진 | E24: 이사 | G24: 솔루션 사업부 | J24: 38292 | L24: 41090 | AC24: =+#REF!+#REF!+#REF!+#REF!+#REF!+#REF!+#REF! -> #REF! | AD24: 0년 0개월 | AE24: 99.166667 | AF24: 8년 3개월
A25: 23 | B25: 120301 | D25: 조성진 | E25: 사원 | G25: PS 팀 | I25: 821224-1226718 | J25: 40973 | L25: 41096 | M25: 전문대 | AC25: =+#REF!+#REF!+#REF!+#REF!+#REF!+#REF!+#REF! -> #REF! | AD25: 0년 0개월 | AE25: 9.8 | AF25: 0년 9개월
A26: 24 | B26: 111101 | D26: 이재철 | E26: 차장 | G26: P A G | I26: 730217-1182811 | J26: 40848 | L26: 41100 | M26: 일반대 | AC26: =+#REF!+#REF!+#REF!+#REF!+#REF!+#REF!+#REF! -> #REF! | AD26: 0년 0개월 | AE26: 13.966667 | AF26: 1년 1개월
A27: 25 | B27: 111204 | D27: 이민현 | E27: 사원 | G27: 플랫폼 사업본부 | I27: 820517-1463111 | J27: 40903 | L27: 41121 | M27: 일반대 | AC27: =+#REF!+#REF!+#REF!+#REF!+#REF!+#REF!+#REF! -> #REF! | AD27: 0년 0개월 | AE27: 12.133333 | AF27: 1년 0개월
A28: 26 | B28: 110801 | D28: 조정현 | E28: 과장 | G28: 플랫폼 사업본부 | I28: 800315-1405519 | J28: 40756 | L28: 41152 | M28: 일반대 | AC28: =+#REF!+#REF!+#REF!+#REF!+#REF!+#REF!+#REF! -> #REF! | AD28: 0년 0개월 | AE28: 17.033333 | AF28: 1년 5개월
A29: 27 | B29: 100502 | D29: 윤용열 | E29: 차장 | G29: PS 팀 | I29: 731215-1037911 | J29: 40329 | L29: 41166 | M29: 전문대 | AC29: =+#REF!+#REF!+#REF!+#REF!+#REF!+#REF!+#REF! -> #REF! | AD29: 0년 0개월 | AE29: 31.266667 | AF29: 2년 7개월
A30: 28 | B30: 100802 | D30: 홍영일 | E30: 팀장 | G30: 플랫폼 사업본부 | I30: 710814-1068926 | J30: 40399 | L30: 41166 | M30: 일반대 | AC30: =+#REF!+#REF!+#REF!+#REF!+#REF!+#REF!+#REF! -> #REF! | AD30: 0년 0개월 | AE30: 28.933333 | AF30: 2년 4개월
A31: 29 | B31: 110103 | D31: 성세현 | E31: 사원 | G31: 플랫폼 사업본부 | I31: 840515-1032717 | J31: 40560 | L31: 41166 | M31: 일반대 | AC31: =+#REF!+#REF!+#REF!+#REF!+#REF!+#REF!+#REF! -> #REF! | AD31: 0년 0개월 | AE31: 23.566667 | AF31: 1년 11개월
A32: 30 | B32: 110202 | D32: 이수민 | E32: 사원 | G32: 플랫폼 사업본부 | I32: 850831-1237528 | J32: 40589 | L32: 41166 | M32: 전문대 | AC32: =+#REF!+#REF!+#REF!+#REF!+#REF!+#REF!+#REF! -> #REF! | AD32: 0년 0개월 | AE32: 22.6 | AF32: 1년 10개월
A33: 31 | B33: 110105 | D33: 이동기 | E33: 사원 | G33: 플랫폼 사업본부 | I33: 820815-1063711 | J33: 40569 | L33: 41182 | M33: 일반대 | AC33: =+#REF!+#REF!+#REF!+#REF!+#REF!+#REF!+#REF! -> #REF! | AD33: 0년 0개월 | AE33: 23.266667 | AF33: 1년 11개월
A34: 32 | B34: 120405 | D34: 이난정 | E34: 대리 | G34: 플랫폼 사업본부 | I34: 851124-2902319 | J34: 41015 | L34: 41182 | M34: 일반대 | AC34: =+#REF!+#REF!+#REF!+#REF!+#REF!+#REF!+#REF! -> #REF! | AD34: 0년 0개월 | AE34: 8.4 | AF34: 0년 8개월
A35: 73 | B35: 120404 | C35: 개발 | D35: 정성신 | E35: 차장 | G35: =+VLOOKUP($B35,#REF!,5,0) -> #REF! | H35: =+VLOOKUP($B35,#REF!,6,0) -> #REF! | I35: 731204-1406310 | J35: 41015 | L35: 41182 | M35: 대학원 | N35: 광운대학교 | Q35: 석사 | Y35: 특급 | Z35: 무 | AC35: =+#REF!+#REF!+#REF!+#REF!+#REF!+#REF!+#REF! -> #REF! | AD35: 0년 0개월 | AE35: 8.4 | AF35: 0년 8개월 | AG35: 8.4 | AH35: 0년 8개월 | AI35: 경기도 성남시 분당구 야탑동 매화마을 312동 501호 | AJ35: 010-5006-5298 | AK35: ssjung@in-soft.co.kr
A36: 50 | B36: 110903 | C36: 개발 | D36: 백승욱 | E36: 대리 | G36: =+VLOOKUP($B36,#REF!,5,0) -> #REF! | H36: =+VLOOKUP($B36,#REF!,6,0) -> #REF! | I36: 831127-1079613 | J36: 40812 | L36: 41201 | M36: 전문대 | N36: 전남대학교 | Q36: 학사 | Y36: 초급 | Z36: 유 | AA36: =+VLOOKUP($D36,[1]Sheet1!$A$1:$C$42,3,0) -> #N/A | AB36: =+VLOOKUP($D36,[1]Sheet1!$A$1:$C$42,2,0) -> #N/A | AC36: =+#REF!+#REF!+#REF!+#REF!+#REF!+#REF!+#REF! -> #REF! | AD36: 0년 0개월 | AE36: 15.166667 | AF36: 1년 3개월 | AG36: 15.166667 | AH36: 1년 3개월 | AI36: 서울시 강동구 천호1동 49-39 경원빌라 101호 | AJ36: 010-9116-8781 | AK36: subaek@in-soft.co.kr
A37: 37 | B37: 101208 | C37: 개발 | D37: 안경배 | E37: 대리 | G37: =+VLOOKUP($B37,#REF!,5,0) -> #REF! | H37: =+VLOOKUP($B37,#REF!,6,0) -> #REF! | I37: 800709-1231310 | J37: 40513 | L37: 41213 | M37: 일반대 | N37: 우석대학교 | Q37: 학사 | Y37: 초급 | Z37: 유 | AA37: =+VLOOKUP($D37,[1]Sheet1!$A$1:$C$42,3,0) -> #N/A | AB37: =+VLOOKUP($D37,[1]Sheet1!$A$1:$C$42,2,0) -> #N/A | AC37: =+#REF!+#REF!+#REF!+#REF!+#REF!+#REF!+#REF! -> #REF! | AD37: 0년 0개월 | AE37: 25.133333 | AF37: 2년 1개월 | AG37: 25.133333 | AH37: 2년 1개월 | AI37: 경기도 군포시 당동 동아아파트 106-303 | AJ37: 010-4711-3779 | AK37: kban@in-soft.co.kr
A38: 73 | B38: 120404 | C38: 개발 | D38: 정성신 | E38: 차장 | G38: =+VLOOKUP($B38,#REF!,5,0) -> #REF! | H38: =+VLOOKUP($B38,#REF!,6,0) -> #REF! | I38: 731204-1406310 | J38: 41015 | L38: 41194 | M38: 대학원 | N38: 광운대학교 | Q38: 석사 | Y38: 특급 | Z38: 무 | AC38: =+#REF!+#REF!+#REF!+#REF!+#REF!+#REF!+#REF! -> #REF! | AD38: 0년 0개월 | AE38: 8.4 | AF38: 0년 8개월 | AG38: 8.4 | AH38: 0년 8개월 | AI38: 경기도 성남시 분당구 야탑동 매화마을 312동 501호 | AJ38: 010-5006-5298 | AK38: ssjung@in-soft.co.kr
A39: 70 | B39: 120401 | C39: 비개발 | D39: 오진석 | E39: 부장 | G39: 영업팀 | H39: 영업팀 | I39: 680825-1041615 | J39: 41001 | L39: 41218 | M39: 일반대 | N39: #N/A | Q39: 학사 | Y39: 고급 | Z39: 유 | AA39: =+VLOOKUP($D39,[1]Sheet1!$A$1:$C$42,3,0) -> #N/A | AB39: =+VLOOKUP($D39,[1]Sheet1!$A$1:$C$42,2,0) -> #N/A | AC39: =+#REF!+#REF!+#REF!+#REF!+#REF!+#REF!+#REF! -> #REF! | AD39: 0년 0개월 | AE39: 8.8666667 | AF39: 0년 8개월 | AG39: 8.8666667 | AH39: 0년 8개월 | AJ39: 010-3239-3630 | AK39: jsoh@in-soft.co.kr
A40: 42 | B40: 110402 | C40: 개발 | D40: 문정식 | E40: 그룹장 | G40: 사업개발2본부 | H40: CMG | I40: 731216-1411313 | J40: 40639 | K40: 2011년 7월 | L40: 41236 | M40: 일반대 | N40: 충남대학교 | O40: 재료공학 | Q40: 학사 | Y40: 고급 | Z40: 무 | AI40: 서울시 동대문구 장안동 장안현대홈타운 112동 404호 | AJ40: 010-2723-7224 | AK40: jsmoon@in-soft.co.kr
...

Sheet 재직자
AK1: date. | AL1: =TODAY() -> 46114
A2: 구분 | B2: 사번 | C2: 구분 | D2: 이름 | F2: 직급 | G2: 과학기술인등록번호 | H2: 소속 | I2: 팀 | J2: 주민등록번호 | K2: 입사일 | L2: 최근승진 | M2: 퇴사일 | N2: 학력 | O2: 학교 | P2: 전공 | Q2: 지역 | R2: 학위 | S2: 학위취득일 | T2: 자격증1 | U2: 합격일 | V2: 자격증2 | W2: 합격일 | X2: 자격증3 | Y2: 합격일 | Z2: 경력기준등급 | AA2: 경력증 | AB2: 취득일 | AC2: 경력증기준등급 | AD2: 전직장 경력(개월) | AE2: 전직장경력년수 | AF2: 근속합계 | AG2: 근속년수 | AH2: 총경력합 | AI2: 총경력년수 | AJ2: 집주소 | AK2: 핸드폰 | AL2: e-mail | AM2: 내선번호 | AN2: 생일 | AO2: 2016년 생일 | AQ2: 가입 | AR2: 성희롱 | AS2: 괴롭힘 | AT2: 장애인
A3: 81 | B3: 220504 | C3: SE, TA | D3: 정구익 | E3: 1 | F3: 과장 | H3: MSP사업본부 | J3: 9001051262312 | K3: 44705 | N3: 대학원 | O3: 숭실대학교 | P3: 정보과학대학원 | Q3: 서울 | R3: 석사 | S3: 44057 | T3: 리눅스마스터2급 | U3: 42636 | V3: OCP 11g | W3: 2016.1 | AD3: 68 | AE3: =(TRUNC(AD3/12))&"년 "&(ROUNDDOWN(MOD(AD3,12),0))&"개월" -> 5년 8개월 | AF3: =($AL$1-K3)/30 -> 46.966667 | AG3: =(TRUNC(AF3/12))&"년 "&(ROUNDDOWN(MOD(AF3,12),0))&"개월" -> 3년 10개월 | AH3: =+AD3+AF3 -> 114.96667 | AI3: =(TRUNC(AH3/12))&"년 "&(ROUNDDOWN(MOD(AH3,12),0))&"개월" -> 9년 6개월 | AJ3: 서울특별시 강서구 화곡동 351-26(더원샵 503호) | AK3: 010-4755-3597 | AL3: gijeong@in-soft.co.kr | AN3: (양)90.01.05 | AQ3: 승인
A4: 115 | B4: 240601 | C4: 개발 | D4: 홍태호 | F4: 차장 | H4: AI사업부문 | I4: MSA Dev팀 | J4: 861208-1009010 | K4: 45446 | N4: 대학원 | O4: 서울시립대학원 | P4: 전기전자컴퓨터공학부 | Q4: 서울 | R4: 석사 | S4: 41327 | T4: 정보처리기사 | U4: 42132 | AC4: 특급 | AD4: 108 | AE4: =(TRUNC(AD4/12))&"년 "&(ROUNDDOWN(MOD(AD4,12),0))&"개월" -> 9년 0개월 | AF4: =(재직자!$AL$1-K4)/30 -> 22.266667 | AG4: =(TRUNC(AF4/12))&"년 "&(ROUNDDOWN(MOD(AF4,12),0))&"개월" -> 1년 10개월 | AH4: =+AD4+AF4 -> 130.26667 | AI4: =(TRUNC(AH4/12))&"년 "&(ROUNDDOWN(MOD(AH4,12),0))&"개월" -> 10년 10개월 | AJ4: 서울시 노원구 마들로1길 44 월계서광아파트 102동 605호 | AK4: 010-4028-1371 | AL4: thhong@in-soft.co.kr | AN4: (양)86.12.08 | AQ4: 승인
A5: 116 | B5: 240602 | C5: 개발 AA | D5: 강재영 | F5: 부장 | H5: AI사업부문 | I5: MSA Dev팀 | J5: 740518-1162812 | K5: 45447 | N5: 일반대 | O5: 건양대학교 | P5: 컴퓨터공학과 | Q5: 논산 | R5: 학사 | AD5: 200 | AE5: =(TRUNC(AD5/12))&"년 "&(ROUNDDOWN(MOD(AD5,12),0))&"개월" -> 16년 8개월 | AF5: =(재직자!$AL$1-K5)/30 -> 22.233333 | AG5: =(TRUNC(AF5/12))&"년 "&(ROUNDDOWN(MOD(AF5,12),0))&"개월" -> 1년 10개월 | AH5: =+AD5+AF5 -> 222.23333 | AI5: =(TRUNC(AH5/12))&"년 "&(ROUNDDOWN(MOD(AH5,12),0))&"개월" -> 18년 6개월 | AJ5: 경기도 수원시 영통구 태장로 71번길 19205동 102호 (동수원 자이2차) | AK5: 010–4510–7477 | AL5: jykang@in-soft.co.kr | AQ5: 승인
A6: 117 | B6: 240603 | C6: 개발-앱 | D6: 손상희 | F6: 부장 | H6: AI사업부문 | I6: MSA Dev팀 | J6: 781020-1920829 | K6: 45450 | N6: 전문대 | O6: 울산과학대학 | P6: 기계설계학부 | Q6: 울산 | R6: 전문 | S6: 37309 | AD6: 151.5 | AE6: =(TRUNC(AD6/12))&"년 "&(ROUNDDOWN(MOD(AD6,12),0))&"개월" -> 12년 7개월 | AF6: =(재직자!$AL$1-K6)/30 -> 22.133333 | AG6: =(TRUNC(AF6/12))&"년 "&(ROUNDDOWN(MOD(AF6,12),0))&"개월" -> 1년 10개월 | AH6: =+AD6+AF6 -> 173.63333 | AI6: =(TRUNC(AH6/12))&"년 "&(ROUNDDOWN(MOD(AH6,12),0))&"개월" -> 14년 5개월 | AJ6: 강서구 화곡동 1107-3 연우넥스트뷰 605 | AK6: 010-4669-1832 | AL6: shson@in-soft.co.kr | AN6: (양)78.02.07 | AQ6: 승인
A7: 118 | B7: 240703 | C7: EN | D7: 홍지환 | F7: 사원 | H7: AI사업부문 | I7: cloud Eng. | J7: 850922-1068611 | K7: 45476 | N7: 일반대 | O7: 국가평생교육진흥원 학점은행 | P7: 컴퓨터네트워크과 | Q7: 기타 | R7: 학사 | S7: 44228 | V7: SQLD | W7: 45261 | X7: 리눅스마스터2급 | Y7: 44105 | Z7: 네트워크관리사2급 | AA7: 43952 | AC7: 초급 | AD7: 38 | AE7: =(TRUNC(AD7/12))&"년 "&(ROUNDDOWN(MOD(AD7,12),0))&"개월" -> 3년 2개월 | AF7: =(재직자!$AL$1-K7)/30 -> 21.266667 | AG7: =(TRUNC(AF7/12))&"년 "&(ROUNDDOWN(MOD(AF7,12),0))&"개월" -> 1년 9개월 | AH7: =+AD7+AF7 -> 59.266667 | AI7: =(TRUNC(AH7/12))&"년 "&(ROUNDDOWN(MOD(AH7,12),0))&"개월" -> 4년 11개월 | AJ7: 경기도 하남시 감일백제로 35 1402동 2501호 | AK7: 010-8030-0307 | AL7: jhhong@in-soft.co.kr | AN7: (양)85.09.22 | AQ7: 승인
A8: 123 | B8: 241101 | C8: 개발 | D8: 최종민 | F8: 부장 | H8: AI사업부문 | I8: MSA Dev팀 | J8: 840502-1380810 | K8: 45614 | N8: 일반대 | O8: University of Sydney, Technology | P8: Computing | Q8: 시드니 | R8: 학사 | S8: 41671 | T8: 정보처리산업기사 | U8: 39314 | AC8: 고급 | AD8: 141 | AE8: =(TRUNC(AD8/12))&"년 "&(ROUNDDOWN(MOD(AD8,12),0))&"개월" -> 11년 9개월 | AF8: =(재직자!$AL$1-K8)/30 -> 16.666667 | AG8: =(TRUNC(AF8/12))&"년 "&(ROUNDDOWN(MOD(AF8,12),0))&"개월" -> 1년 4개월 | AH8: =+AD8+AF8 -> 157.66667 | AI8: =(TRUNC(AH8/12))&"년 "&(ROUNDDOWN(MOD(AH8,12),0))&"개월" -> 13년 1개월 | AJ8: 서울시 동대문구 홍릉로 8길 23 | AK8: 010-7700-6087 | AL8: jmchoi@in-soft.co.kr | AN8: (양)84.05.02 | AQ8: 승인
A9: 124 | B9: 241102 | C9: 개발 | D9: 박범진 | F9: 차장 | H9: AI사업부문 | I9: MSA Dev팀 | J9: 841227-1000000 | K9: 45614 | N9: 일반대 | O9: 한서대학교 | P9: 컴퓨터정보공학과 | Q9: 충남 | R9: 학사 | S9: 40232 | T9: 정보처리기사 | U9: 39965 | AC9: 특급 | AD9: 161 | AE9: =(TRUNC(AD9/12))&"년 "&(ROUNDDOWN(MOD(AD9,12),0))&"개월" -> 13년 5개월 | AF9: =(재직자!$AL$1-K9)/30 -> 16.666667 | AG9: =(TRUNC(AF9/12))&"년 "&(ROUNDDOWN(MOD(AF9,12),0))&"개월" -> 1년 4개월 | AH9: =+AD9+AF9 -> 177.66667 | AI9: =(TRUNC(AH9/12))&"년 "&(ROUNDDOWN(MOD(AH9,12),0))&"개월" -> 14년 9개월 | AJ9: 인천 미추홀구 주안1동 265-25 두울아파트 | AK9: 010-2854-6549 | AL9: bjpark@in-soft.co.kr | AN9: (양)84.12.27 | AQ9: 승인
A10: 125 | B10: 241103 | C10: 개발 | D10: 한영우 | F10: 부장 | H10: AI사업부문 | I10: MSA Dev팀 | J10: 760912-1029722 | K10: 45615 | N10: 일반대 | O10: 중앙대학교 | P10: 컴퓨터공학과 | Q10: 서울 | R10: 학사 | S10: 37653 | AC10: 특급 | AD10: 221.7 | AE10: =(TRUNC(AD10/12))&"년 "&(ROUNDDOWN(MOD(AD10,12),0))&"개월" -> 18년 5개월 | AF10: =(재직자!$AL$1-K10)/30 -> 16.633333 | AG10: =(TRUNC(AF10/12))&"년 "&(ROUNDDOWN(MOD(AF10,12),0))&"개월" -> 1년 4개월 | AH10: =+AD10+AF10 -> 238.33333 | AI10: =(TRUNC(AH10/12))&"년 "&(ROUNDDOWN(MOD(AH10,12),0))&"개월" -> 19년 10개월 | AJ10: 서울시 금천구 벚꽃로 40 금천롯데캐슬골드파크1차아파트 111-606 | AK10: 010-8918-1281 | AQ10: 승인
A11: 126 | C11: 개발 | D11: 최진우 | F11: 부장 | H11: AI사업부문 | AQ11: 승인
A12: 46 | B12: 200903 | C12: SE | D12: 이상목 | E12: 1 | F12: 차장 | H12: MSP사업본부 | J12: 810514-1163011 | K12: 44095 | N12: 일반대 | O12: 세종사이버대학교 | P12: 유비쿼터스컴퓨팅 | Q12: 서울 | R12: 학사 | S12: 40055 | AD12: 175 | AE12: =(TRUNC(AD12/12))&"년 "&(ROUNDDOWN(MOD(AD12,12),0))&"개월" -> 14년 7개월 | AF12: =($AL$1-K12)/30 -> 67.3 | AG12: =(TRUNC(AF12/12))&"년 "&(ROUNDDOWN(MOD(AF12,12),0))&"개월" -> 5년 7개월 | AH12: =+AD12+AF12 -> 242.3 | AI12: =(TRUNC(AH12/12))&"년 "&(ROUNDDOWN(MOD(AH12,12),0))&"개월" -> 20년 2개월 | AJ12: 서울시 도봉구 방학로11길33, 101동 409호 | AK12: 010-4177-4006 | AL12: lsm@in-soft.co.kr | AN12: (양)81.05.14 | AO12: 05.14 | AQ12: 승인
A13: 40 | B13: 200202 | C13: SE | D13: 강명완 | E13: 1 | F13: 부장 | H13: MSP사업본부 | J13: 800315-1018319 | K13: 43864 | L13: 44562 | N13: 전문대 | O13: 현대직업전문학교 | P13: 컴퓨터네트워크 | Q13: 서울 | R13: 전문 | S13: 36950 | V13: MCP | X13: CCNA | AD13: 175 | AE13: =(TRUNC(AD13/12))&"년 "&(ROUNDDOWN(MOD(AD13,12),0))&"개월" -> 14년 7개월 | AF13: =($AL$1-K13)/30 -> 75 | AG13: =(TRUNC(AF13/12))&"년 "&(ROUNDDOWN(MOD(AF13,12),0))&"개월" -> 6년 3개월 | AH13: =+AD13+AF13 -> 250 | AI13: =(TRUNC(AH13/12))&"년 "&(ROUNDDOWN(MOD(AH13,12),0))&"개월" -> 20년 10개월 | AJ13: 서울시 노원구 상계동 한글비석로 396 벽산아파트 107동 1406호 | AK13: 010-8587-4562 | AL13: mwkang@in-soft.co.kr | AN13: (양)80.03.15 | AO13: 03.15 | AQ13: 승인
A14: 52 | B14: 210203 | C14: SE | D14: 유재동 | E14: 1 | F14: 대리 | H14: MSP사업본부 | J14: 880923-1068916 | K14: 44228 | N14: 일반대 | O14: 관동대학교 | P14: 호텔조리 | Q14: 강원 | R14: 학사 | S14: 42782 | V14: 네트워크관리사2급 | W14: 43081 | AD14: 29 | AE14: =(TRUNC(AD14/12))&"년 "&(ROUNDDOWN(MOD(AD14,12),0))&"개월" -> 2년 5개월 | AF14: =($AL$1-K14)/30 -> 62.866667 | AG14: =(TRUNC(AF14/12))&"년 "&(ROUNDDOWN(MOD(AF14,12),0))&"개월" -> 5년 2개월 | AH14: =+AD14+AF14 -> 91.866667 | AI14: =(TRUNC(AH14/12))&"년 "&(ROUNDDOWN(MOD(AH14,12),0))&"개월" -> 7년 7개월 | AJ14: 경기도 성남시 중원구 광명로89 센트럴 푸르지오 시티 A동 1119호 | AK14: 010-5691-4456 | AL14: jdyoo@in-soft.co.kr | AN14: (양)88.09.23 | AO14: 09.23 | AQ14: 승인
A15: 57 | B15: 210507 | C15: SE | D15: 방지훈 | E15: 1 | F15: 차장 | H15: MSP사업본부 | J15: 821002-1075112 | K15: 44340 | N15: 일반대 | O15: 경동대학교 | P15: 컴퓨터공학 | Q15: 강원 | R15: 학사 | S15: 39858 | T15: 정보처리기능사 | U15: 36523 | AD15: 143 | AE15: =(TRUNC(AD15/12))&"년 "&(ROUNDDOWN(MOD(AD15,12),0))&"개월" -> 11년 11개월 | AF15: =($AL$1-K15)/30 -> 59.133333 | AG15: =(TRUNC(AF15/12))&"년 "&(ROUNDDOWN(MOD(AF15,12),0))&"개월" -> 4년 11개월 | AH15: =+AD15+AF15 -> 202.13333 | AI15: =(TRUNC(AH15/12))&"년 "&(ROUNDDOWN(MOD(AH15,12),0))&"개월" -> 16년 10개월 | AJ15: 서울시 성북구 종암로23길 35, 201동 101호 (종암동, 래미안세레니티) | AK15: 010-2642-0181 | AL15: jhbang@in-soft.co.kr | AN15: (양)82.10.02 | AO15: 10.02 | AQ15: 승인
A16: 96 | B16: 230107 | C16: EN | D16: 박성현 | E16: 1 | F16: 차장 | H16: MSP사업본부 | I16: CA팀 | J16: 820814-1536115 | K16: 44942 | N16: 일반대 | O16: 방송통신대학교 | P16: 컴퓨터과 | Q16: 서울 | R16: 학사 | S16: 43133 | T16: 네트워크관리사2급 | U16: 42899 | V16: Certified Kubernetes Administrator (CKA) | W16: 44926 | X16: AWS Certified Cloud Practitioner | Y16: 45164 | AD16: 161 | AE16: =(TRUNC(AD16/12))&"년 "&(ROUNDDOWN(MOD(AD16,12),0))&"개월" -> 13년 5개월 | AF16: =($AL$1-K16)/30 -> 39.066667 | AG16: =(TRUNC(AF16/12))&"년 "&(ROUNDDOWN(MOD(AF16,12),0))&"개월" -> 3년 3개월 | AH16: =+AD16+AF16 -> 200.06667 | AI16: =(TRUNC(AH16/12))&"년 "&(ROUNDDOWN(MOD(AH16,12),0))&"개월" -> 16년 8개월 | AJ16: 서울시 양천구 목동중앙본로2길 38-40 성재캐슬빌 301호 | AK16: 010-5442-9349 | AL16: shpark@in-soft.co.kr | AN16: (양)82.08.14 | AQ16: 승인
A17: 37 | B17: 200102 | C17: 본부장 | D17: 이태운 | E17: 2 | F17: 이사 | H17: MSP사업본부 | J17: 731223-1064029 | K17: 43843 | N17: 대학원 | O17: 서울과학종합대학원 | P17: 경영전문석사(MBA) | Q17: 서울 | R17: 석사 | S17: 42237 | T17: AWS Certified Advanced Networking-Specialty | U17: 44742 | AD17: 203 | AE17: =(TRUNC(AD17/12))&"년 "&(ROUNDDOWN(MOD(AD17,12),0))&"개월" -> 16년 11개월 | AF17: =(재직자!$AL$1-K17)/30 -> 75.7 | AG17: =(TRUNC(AF17/12))&"년 "&(ROUNDDOWN(MOD(AF17,12),0))&"개월" -> 6년 3개월 | AH17: =+AD17+AF17 -> 278.7 | AI17: =(TRUNC(AH17/12))&"년 "&(ROUNDDOWN(MOD(AH17,12),0))&"개월" -> 23년 2개월 | AJ17: 서울시 강서구 방화동 876, 방화2차 마곡우림필유아파트 103동 1004호 | AK17: 010-7132-6361 | AL17: twlee@in-soft.co.kr | AN17: (양)73.12.23 | AO17: 12.23 | AQ17: 승인
A18: 48 | B18: 201202 | C18: SE | D18: 문효진 | E18: 2 | F18: 사원 | H18: MSP사업본부 | J18: 910818-2064114 | K18: 44186 | N18: 일반대 | O18: 한국방송통신대학교 | P18: 경영학과 | Q18: 서울 | R18: 학사 | S18: 졸업예정 | T18: Naver Cloud Platform Certified Associate | U18: 44321 | V18: AWS Certified Solutions Architect - Professional | W18: 44263 | X18: 리눅스마스터 | Y18: 44127 | AD18: 0 | AE18: =(TRUNC(AD18/12))&"년 "&(ROUNDDOWN(MOD(AD18,12),0))&"개월" -> 0년 0개월 | AF18: =($AL$1-K18)/30 -> 64.266667 | AG18: =(TRUNC(AF18/12))&"년 "&(ROUNDDOWN(MOD(AF18,12),0))&"개월" -> 5년 4개월 | AH18: =+AD18+AF18 -> 64.266667 | AI18: =(TRUNC(AH18/12))&"년 "&(ROUNDDOWN(MOD(AH18,12),0))&"개월" -> 5년 4개월 | AJ18: 서울시 강서구 강서로56나길 110, 106동 1201호 | AK18: 010-7387-1587 | AL18: hjmoon@in-soft.co.kr | AN18: (양)91.08.18 | AO18: 08.18 | AQ18: 승인
A19: 87 | B19: 221001 | C19: EN | D19: 이항원 | E19: 2 | F19: 차장 | H19: MSP사업본부 | J19: 831118-1032528 | K19: 44838 | N19: 전문대 | O19: 두원공과대학 | P19: 경영학과 | Q19: 경기 | R19: 전문 | S19: 39492 | AD19: 157 | AE19: =(TRUNC(AD19/12))&"년 "&(ROUNDDOWN(MOD(AD19,12),0))&"개월" -> 13년 1개월 | AF19: =($AL$1-K19)/30 -> 42.533333 | AG19: =(TRUNC(AF19/12))&"년 "&(ROUNDDOWN(MOD(AF19,12),0))&"개월" -> 3년 6개월 | AH19: =+AD19+AF19 -> 199.53333 | AI19: =(TRUNC(AH19/12))&"년 "&(ROUNDDOWN(MOD(AH19,12),0))&"개월" -> 16년 7개월 | AJ19: 서울시 노원구 월계동 392-33번지 이레리치빌 401호 | AK19: 010-9228-2631 | AL19: hwlee@in-soft.co.kr | AN19: (양)83.11.18 | AQ19: 승인
A20: 103 | B20: 230601 | C20: DBA | D20: 조선희 | E20: 2 | F20: 차장 | H20: MSP사업본부 | I20: MOC팀 | J20: 810324-1051714 | K20: 45096 | N20: 전문대 | O20: 부천대학교 | P20: e-business | Q20: 부천 | R20: 전문학사 | S20: 38768 | T20: sql개발자 | U20: 42927 | AC20: 고급 | AD20: 167 | AE20: =(TRUNC(AD20/12))&"년 "&(ROUNDDOWN(MOD(AD20,12),0))&"개월" -> 13년 11개월 | AF20: =($AL$1-K20)/30 -> 33.933333 | AG20: =(TRUNC(AF20/12))&"년 "&(ROUNDDOWN(MOD(AF20,12),0))&"개월" -> 2년 9개월 | AH20: =+AD20+AF20 -> 200.93333 | AI20: =(TRUNC(AH20/12))&"년 "&(ROUNDDOWN(MOD(AH20,12),0))&"개월" -> 16년 8개월 | AJ20: 경기도 용인시 기흥구 동백죽전대로527번길 67 신동백롯데캐슬 에코2단지 206동1102호 | AK20: 010-4223-3600 | AL20: shcho@in-soft.co.kr | AN20: (음)81.02.19 | AQ20: 승인
A21: 109 | B21: 230803 | C21: EN | D21: 전병찬 | E21: 2 | F21: 대리 | H21: MSP사업본부 | I21: MOC팀 | J21: 970729-1029314 | K21: 45159 | N21: 고졸 | O21: 송현고등학교 | Q21: 경기 | R21: 고졸 | S21: 42401 | T21: 리눅스마스터2급 | U21: 44288 | V21: 네트워크관리사2급 | W21: 43893 | AD21: 37.9 | AE21: =(TRUNC(AD21/12))&"년 "&(ROUNDDOWN(MOD(AD21,12),0))&"개월" -> 3년 1개월 | AF21: =($AL$1-K21)/30 -> 31.833333 | AG21: =(TRUNC(AF21/12))&"년 "&(ROUNDDOWN(MOD(AF21,12),0))&"개월" -> 2년 7개월 | AH21: =+AD21+AF21 -> 69.733333 | AI21: =(TRUNC(AH21/12))&"년 "&(ROUNDDOWN(MOD(AH21,12),0))&"개월" -> 5년 9개월 | AJ21: 경기도 구리시 수택천로25번길 4 우건빌리지 101동 502호 | AK21: 010-4221-1045 | AL21: bcjeon@in-soft.co.kr | AN21: (양)97.07.29 | AQ21: 승인
A22: 107 | B22: 230704 | C22: EN | D22: 박도윤 | F22: 사원 | H22: MSP사업본부 | I22: moc팀 | J22: 941220-2063919 | K22: 45131 | N22: 일반대 | O22: 동국대학 | P22: 가정교육과 | Q22: 경북 | R22: 학사 | S22: 42767 | T22: Microsoft Certified: Azure Fundamentals | U22: 45118 | V22: CCNA (Cisco Certification Network Associate) | W22: 44039 | X22: 네트워크관리사2급 | Y22: 43956 | AD22: 23 | AE22: =(TRUNC(AD22/12))&"년 "&(ROUNDDOWN(MOD(AD22,12),0))&"개월" -> 1년 11개월 | AF22: =($AL$1-K22)/30 -> 32.766667 | AG22: =(TRUNC(AF22/12))&"년 "&(ROUNDDOWN(MOD(AF22,12),0))&"개월" -> 2년 8개월 | AH22: =+AD22+AF22 -> 55.766667 | AI22: =(TRUNC(AH22/12))&"년 "&(ROUNDDOWN(MOD(AH22,12),0))&"개월" -> 4년 7개월 | AJ22: 서울시 강서구 가로공원로 200-26,202호 | AK22: 010-3563-4330 | AL22: dypark@in-soft.co.kr | AN22: (양)94.12.20 | AQ22: 승인
A23: 104 | B23: 230701 | C23: 본부장 | D23: 이승용 | E23: 1 | F23: 전무 | H23: PMO및사업관리본부 | J23: 630521-1455313 | K23: 45110 | N23: 대학원 | O23: 세종대학원 | P23: 정보통신학 | R23: 석사 | S23: 37491 | T23: 정보처리기사 | U23: 34072 | V23: CCNA | W23: 41523 | AD23: 455 | AE23: =(TRUNC(AD23/12))&"년 "&(ROUNDDOWN(MOD(AD23,12),0))&"개월" -> 37년 11개월 | AF23: =($AL$1-K23)/30 -> 33.466667 | AG23: =(TRUNC(AF23/12))&"년 "&(ROUNDDOWN(MOD(AF23,12),0))&"개월" -> 2년 9개월 | AH23: =+AD23+AF23 -> 488.46667 | AI23: =(TRUNC(AH23/12))&"년 "&(ROUNDDOWN(MOD(AH23,12),0))&"개월" -> 40년 8개월 | AJ23: 경기도 성남시 분당구 판교원로 81번길 | AK23: 010-3710-9757 | AL23: srlee05@in-soft.co.kr | AN23: (양)63.05.21 | AQ23: 승인
A24: 108 | B24: 230802 | C24: PM | D24: 김민우 | E24: 1 | F24: 이사 | H24: PMO및사업관리본부 | I24: 사업지원팀 | J24: 700315-1155111 | K24: 45159 | N24: 전문대 | O24: 인천전문대학교 | P24: 전자계산 | Q24: 인천 | R24: 전문학사 | S24: 34366 | T24: 정보처리산업기사 | U24: 34274 | V24: CISA | W24: 39330 | AD24: 348 | AE24: =(TRUNC(AD24/12))&"년 "&(ROUNDDOWN(MOD(AD24,12),0))&"개월" -> 29년 0개월 | AF24: =($AL$1-K24)/30 -> 31.833333 | AG24: =(TRUNC(AF24/12))&"년 "&(ROUNDDOWN(MOD(AF24,12),0))&"개월" -> 2년 7개월 | AH24: =+AD24+AF24 -> 379.83333 | AI24: =(TRUNC(AH24/12))&"년 "&(ROUNDDOWN(MOD(AH24,12),0))&"개월" -> 31년 7개월 | AJ24: 서울특별시 구로구 개봉로3길 87 104동 103호(개봉동, 개봉한진아파트) | AK24: 010-6334-2872 | AL24: mwkim@in-soft.co.kr | AN24: (양)70.03.15
A25: 105 | B25: 230702 | C25: pm,기획 | D25: 이문수 | F25: 이사 | H25: PMO및사업관리본부 | J25: 730820-1036713 | K25: 45118 | N25: 일반대 | O25: 한국방송통신대학교 | P25: 경영학과 | Q25: 서울 | R25: 학사 | S25: 41689 | T25: 정보처리기능사 | U25: 36325 | V25: 정보기기운용기능사 | W25: 36381 | AD25: 254 | AE25: =(TRUNC(AD25/12))&"년 "&(ROUNDDOWN(MOD(AD25,12),0))&"개월" -> 21년 2개월 | AF25: =($AL$1-K25)/30 -> 33.2 | AG25: =(TRUNC(AF25/12))&"년 "&(ROUNDDOWN(MOD(AF25,12),0))&"개월" -> 2년 9개월 | AH25: =+AD25+AF25 -> 287.2 | AI25: =(TRUNC(AH25/12))&"년 "&(ROUNDDOWN(MOD(AH25,12),0))&"개월" -> 23년 11개월 | AJ25: 서울시 금천구 가산디지철2로 160-37, B동 1211gh(가산동) | AK25: 010-3038-8912 | AL25: mslee@in-soft.co.kr | AN25: (양)73.08.20 | AQ25: 승인
A26: 97 | B26: 230202 | C26: PM | D26: 손수유 | E26: 1 | F26: 부장 | H26: PMO및사업관리본부 | J26: 730308-1023123 | K26: 44958 | N26: 일반대 | O26: 서경대학교 | P26: 컴퓨터과학 | Q26: 서울 | R26: 학사 | S26: 36210 | T26: 정보처리기사 | U26: 36081 | AD26: 267 | AE26: =(TRUNC(AD26/12))&"년 "&(ROUNDDOWN(MOD(AD26,12),0))&"개월" -> 22년 3개월 | AF26: =($AL$1-K26)/30 -> 38.533333 | AG26: =(TRUNC(AF26/12))&"년 "&(ROUNDDOWN(MOD(AF26,12),0))&"개월" -> 3년 2개월 | AH26: =+AD26+AF26 -> 305.53333 | AI26: =(TRUNC(AH26/12))&"년 "&(ROUNDDOWN(MOD(AH26,12),0))&"개월" -> 25년 5개월 | AJ26: 서울시 종로구 동망산길 120, 301호 (숭인동, 할리우드파크아파트) | AK26: 010-5037-5111 | AL26: syson@in-soft.co.kr | AN26: (양)73.03.08 | AQ26: 승인
A27: 43 | B27: 200501 | C27: 비개발 | D27: 권보람 | E27: 1 | F27: 대리 | H27: 경영지원본부 | I27: NIA사업팀 | J27: 890111-2794417 | K27: 43958 | L27: 44228 | N27: 일반대 | O27: 계명대학교 | P27: 스페인어중남미학 | Q27: 대구 | R27: 학사 | S27: 40955 | AD27: 29 | AE27: =(TRUNC(AD27/12))&"년 "&(ROUNDDOWN(MOD(AD27,12),0))&"개월" -> 2년 5개월 | AF27: =($AL$1-K27)/30 -> 71.866667 | AG27: =(TRUNC(AF27/12))&"년 "&(ROUNDDOWN(MOD(AF27,12),0))&"개월" -> 5년 11개월 | AH27: =+AD27+AF27 -> 100.86667 | AI27: =(TRUNC(AH27/12))&"년 "&(ROUNDDOWN(MOD(AH27,12),0))&"개월" -> 8년 4개월 | AJ27: 대구시 수성구 명덕로76길 111-4 | AK27: 010-3793-2706 | AL27: brkwon@in-soft.co.kr | AN27: (양)89.01.11 | AO27: 01.11 | AQ27: 승인
A28: 49 | B28: 210103 | C28: 비개발 | D28: 김주영 | E28: 1 | F28: 차장 | G28: 1181 0219 | H28: 경영지원본부 | I28: NIA사업팀 | J28: 760117-2683219 | K28: 44221 | N28: 전문대 | O28: 영진전문대학 | P28: 산업디자인 | Q28: 대구 | R28: 전문 | S28: 38037 | AD28: 234 | AE28: =(TRUNC(AD28/12))&"년 "&(ROUNDDOWN(MOD(AD28,12),0))&"개월" -> 19년 6개월 | AF28: =($AL$1-K28)/30 -> 63.1 | AG28: =(TRUNC(AF28/12))&"년 "&(ROUNDDOWN(MOD(AF28,12),0))&"개월" -> 5년 3개월 | AH28: =+AD28+AF28 -> 297.1 | AI28: =(TRUNC(AH28/12))&"년 "&(ROUNDDOWN(MOD(AH28,12),0))&"개월" -> 24년 9개월 | AJ28: 경북 경산시 경안로69길 12 104동 1406호 (대평동, 대평그린빌) | AK28: 010-3827-1481 | AL28: jykim@in-soft.co.kr | AN28: (양)76.01.17 | AO28: 01.17 | AQ28: 승인
A29: 64 | B29: 211002 | C29: 비개발 | D29: 김재학 | E29: 1 | F29: 이사 | H29: 경영지원본부 | I29: 경영지원팀 | J29: 680125-1094513 | K29: 44496 | N29: 고졸 | O29: 대동고등학교 | P29: 인문계 | Q29: 부산 | R29: 고졸 | S29: 31836 | AD29: 200 | AE29: =(TRUNC(AD29/12))&"년 "&(ROUNDDOWN(MOD(AD29,12),0))&"개월" -> 16년 8개월 | AF29: =($AL$1-K29)/30 -> 53.933333 | AG29: =(TRUNC(AF29/12))&"년 "&(ROUNDDOWN(MOD(AF29,12),0))&"개월" -> 4년 5개월 | AH29: =+AD29+AF29 -> 253.93333 | AI29: =(TRUNC(AH29/12))&"년 "&(ROUNDDOWN(MOD(AH29,12),0))&"개월" -> 21년 1개월 | AJ29: 서울시 금천구 가산동 148-21 301호 | AK29: 010-2570-1106 | AL29: jaehak@in-soft.co.kr | AN29: (음)68.01.25 | AO29: 01.25 | AQ29: 승인
A30: 19 | B30: 140702 | C30: PM | D30: 최성현 | E30: 2 | F30: 부장 | G30: 1139 0323 | H30: 경영지원본부 | I30: NIA사업팀 | J30: 760504-1388213 | K30: 41821 | L30: 43891 | N30: 전문대 | O30: 공주영상정보대학 | P30: 경영학 | Q30: 충남 | R30: 전문 | S30: 35472 | Z30: 고급 | AD30: 147 | AE30: =(TRUNC(AD30/12))&"년 "&(ROUNDDOWN(MOD(AD30,12),0))&"개월" -> 12년 3개월 | AF30: =($AL$1-K30)/30 -> 143.1 | AG30: =(TRUNC(AF30/12))&"년 "&(ROUNDDOWN(MOD(AF30,12),0))&"개월" -> 11년 11개월 | AH30: =+AD30+AF30 -> 290.1 | AI30: =(TRUNC(AH30/12))&"년 "&(ROUNDDOWN(MOD(AH30,12),0))&"개월" -> 24년 2개월 | AJ30: 경기도 용인시 수지구 광교마을로 90 4109동 1707호 | AK30: 010-4507-1922 | AL30: shchoi@in-soft.co.kr | AN30: (양)76.05.04 | AO30: 5.04 | AQ30: 승인
A31: 42 | B31: 200301 | C31: 개발 | D31: 최준영 | E31: 2 | F31: 대리 | H31: 경영지원본부 | I31: NIA사업팀 | J31: 900309-1692715 | K31: 43892 | L31: 44228 | N31: 전문대 | O31: 영진전문대학 | P31: 컴퓨터정보 | Q31: 대구 | R31: 전문 | S31: 42776 | AD31: 30 | AE31: =(TRUNC(AD31/12))&"년 "&(ROUNDDOWN(MOD(AD31,12),0))&"개월" -> 2년 6개월 | AF31: =($AL$1-K31)/30 -> 74.066667 | AG31: =(TRUNC(AF31/12))&"년 "&(ROUNDDOWN(MOD(AF31,12),0))&"개월" -> 6년 2개월 | AH31: =+AD31+AF31 -> 104.06667 | AI31: =(TRUNC(AH31/12))&"년 "&(ROUNDDOWN(MOD(AH31,12),0))&"개월" -> 8년 8개월 | AJ31: 대구시 달서구 송현2동 530-9번지 | AK31: 010-6700-1051 | AL31: jychoi@in-soft.co.kr | AN31: (양)90.03.09 | AO31: 03.09 | AQ31: 승인
A32: 51 | B32: 210201 | C32: SE | D32: 심용민 | E32: 2 | F32: 과장 | H32: 경영지원본부 | I32: NIA사업팀 | J32: 891009-1673617 | K32: 44228 | L32: 44562 | N32: 일반대 | O32: 국가평생교육진흥원 | P32: 검퓨터공학 | Q32: 대구 | R32: 학사 | S32: 43153 | T32: 정보처리산업기사 | U32: 42132 | AD32: 74 | AE32: =(TRUNC(AD32/12))&"년 "&(ROUNDDOWN(MOD(AD32,12),0))&"개월" -> 6년 2개월 | AF32: =($AL$1-K32)/30 -> 62.866667 | AG32: =(TRUNC(AF32/12))&"년 "&(ROUNDDOWN(MOD(AF32,12),0))&"개월" -> 5년 2개월 | AH32: =+AD32+AF32 -> 136.86667 | AI32: =(TRUNC(AH32/12))&"년 "&(ROUNDDOWN(MOD(AH32,12),0))&"개월" -> 11년 4개월 | AJ32: 대구시 동구 아양로 11길 81-34 진주빌라 501 | AK32: 010-4512-9329 | AL32: ymshim@in-soft.co.kr | AN32: (양)89.10.09 | AO32: 10.09 | AQ32: 승인
A33: 62 | B33: 210801 | C33: 비개발 | D33: 김동환 | E33: 2 | F33: 과장 | H33: 경영지원본부 | I33: 경영지원팀 | J33: 830401-1067513 | K33: 44410 | N33: 일반대 | O33: 수원대학교 | P33: 호텔관광경영 | Q33: 경기 | R33: 학사 | S33: 40410 | AD33: 99 | AE33: =(TRUNC(AD33/12))&"년 "&(ROUNDDOWN(MOD(AD33,12),0))&"개월" -> 8년 3개월 | AF33: =($AL$1-K33)/30 -> 56.8 | AG33: =(TRUNC(AF33/12))&"년 "&(ROUNDDOWN(MOD(AF33,12),0))&"개월" -> 4년 8개월 | AH33: =+AD33+AF33 -> 155.8 | AI33: =(TRUNC(AH33/12))&"년 "&(ROUNDDOWN(MOD(AH33,12),0))&"개월" -> 12년 11개월 | AJ33: 서울시 관악구 신림동 1441-6, 3층 | AK33: 010-8910-2220 | AL33: dhk@in-soft.co.kr | AN33: (양)83.04.01 | AO33: 04.01 | AQ33: 승인
A34: 75 | B34: 220302 | C34: 개발 | D34: 김건우 | E34: 2 | F34: 사원 | H34: 경영지원본부 | I34: NIA사업팀 | J34: 930524-1779011 | K34: 44627 | N34: 일반대 | O34: 대구대학교 | P34: 건축공학 | Q34: 대구 | R34: 학사 | S34: 43518 | AD34: 0 | AE34: =(TRUNC(AD34/12))&"년 "&(ROUNDDOWN(MOD(AD34,12),0))&"개월" -> 0년 0개월 | AF34: =($AL$1-K34)/30 -> 49.566667 | AG34: =(TRUNC(AF34/12))&"년 "&(ROUNDDOWN(MOD(AF34,12),0))&"개월" -> 4년 1개월 | AH34: =+AD34+AF34 -> 49.566667 | AI34: =(TRUNC(AH34/12))&"년 "&(ROUNDDOWN(MOD(AH34,12),0))&"개월" -> 4년 1개월 | AJ34: 대구시 서구 국채보상로 316, (평리동, 평리롯데캐슬) | AK34: 010-5150-4642 | AL34: gwkim@in-soft.co.kr | AN34: (양)93.05.24 | AO34: 05.24 | AQ34: 승인
A35: 85 | B35: 220905 | C35: 비개발 | D35: 추연경 | E35: 2 | F35: 대리 | H35: 경영지원본부 | I35: NIA사업팀 | J35: 871010-2697014 | K35: 44817 | N35: 전문대 | O35: 영진 전문대 | P35: 디지털경영 | Q35: 대구 | R35: 전문 | AD35: 95 | AE35: =(TRUNC(AD35/12))&"년 "&(ROUNDDOWN(MOD(AD35,12),0))&"개월" -> 7년 11개월 | AF35: =($AL$1-K35)/30 -> 43.233333 | AG35: =(TRUNC(AF35/12))&"년 "&(ROUNDDOWN(MOD(AF35,12),0))&"개월" -> 3년 7개월 | AH35: =+AD35+AF35 -> 138.23333 | AI35: =(TRUNC(AH35/12))&"년 "&(ROUNDDOWN(MOD(AH35,12),0))&"개월" -> 11년 6개월 | AJ35: 대구 동구 동화천로 77길 30, 312동 703호 | AK35: 010-4807-0665 | AL35: ykchu@in-soft.co.kr | AN35: (양)87.10.10 | AQ35: 승인
A36: 113 | B36: 240401 | C36: 개발 | D36: 장윤경 | E36: 2 | F36: 사원 | H36: 경영지원본부 | I36: NIA사업팀 | J36: 960726-2686120 | K36: 45383 | N36: 전문대 | O36: 계명문화대학교 | P36: 뷰티코디네이션과 | Q36: 대구 | R36: 전문학사 | S36: 42776 | T36: 웹디자인기능사 | U36: 44812 | AD36: 0 | AE36: =(TRUNC(AD36/12))&"년 "&(ROUNDDOWN(MOD(AD36,12),0))&"개월" -> 0년 0개월 | AF36: =(재직자!$AL$1-K36)/30 -> 24.366667 | AG36: =(TRUNC(AF36/12))&"년 "&(ROUNDDOWN(MOD(AF36,12),0))&"개월" -> 2년 0개월 | AH36: =+AD36+AF36 -> 24.366667 | AI36: =(TRUNC(AH36/12))&"년 "&(ROUNDDOWN(MOD(AH36,12),0))&"개월" -> 2년 0개월 | AJ36: 대구 남구 대명복개로192 세신아파트 가동 206호 | AK36: 010-4907-6646 | AL36: ygjang@in-soft.co.kr | AN36: (양)96.07.26 | AQ36: 승인
A37: 95 | B37: 230103 | C37: 기타 | D37: 박수민 | E37: 2 | F37: 대리 | H37: 경영지원본부 | I37: NIA사업팀 | J37: 930503-2632218 | K37: 44928 | N37: 일반대 | O37: 동국대학교(경주) | P37: 관광레저경영 | Q37: 경북 | R37: 학사 | AD37: 66 | AE37: =(TRUNC(AD37/12))&"년 "&(ROUNDDOWN(MOD(AD37,12),0))&"개월" -> 5년 6개월 | AF37: =($AL$1-K37)/30 -> 39.533333 | AG37: =(TRUNC(AF37/12))&"년 "&(ROUNDDOWN(MOD(AF37,12),0))&"개월" -> 3년 3개월 | AH37: =+AD37+AF37 -> 105.53333 | AI37: =(TRUNC(AH37/12))&"년 "&(ROUNDDOWN(MOD(AH37,12),0))&"개월" -> 8년 9개월 | AJ37: 대구광역시 동구 메디밸리로 18 1003동 1104호 | AK37: 010-8010-4032 | AL37: sm050365@gmail.com | AN37: (양)93.05.03 | AQ37: 승인
A38: 102 | B38: 230304 | C38: 웹퍼블리셔 | D38: 성수진 | E38: 2 | F38: 대리 | H38: 경영지원본부 | I38: NIA 사업팀 | J38: 921106-2692611 | K38: 45012 | N38: 전문대 | O38: 계명문화대학교 | P38: 광고디자인과 | Q38: 대구 | R38: 전문학사 | S38: 41683 | T38: 정보처리기능사 | U38: 38567 | V38: 웹디자인기능사 | W38: 43007 | X38: GTQ포토샵1급 | Y38: 42867 | AD38: 84 | AE38: =(TRUNC(AD38/12))&"년 "&(ROUNDDOWN(MOD(AD38,12),0))&"개월" -> 7년 0개월 | AF38: =($AL$1-K38)/30 -> 36.733333 | AG38: =(TRUNC(AF38/12))&"년 "&(ROUNDDOWN(MOD(AF38,12),0))&"개월" -> 3년 0개월 | AH38: =+AD38+AF38 -> 120.73333 | AI38: =(TRUNC(AH38/12))&"년 "&(ROUNDDOWN(MOD(AH38,12),0))&"개월" -> 10년 0개월 | AJ38: 대구광역시 달서구 중흥로13길 30-8, A동 202호 | AK38: 010-9359-2975 | AL38: sjseong@in-soft.co.kr | AN38: (양)92.11.06 | AQ38: 승인
A39: 56 | B39: 210504 | C39: 비개발 | D39: 조호지 | E39: 2 | F39: 대리 | H39: 경영지원본부 | I39: NIA사업팀 | J39: 860116-2109324 | K39: 44329 | N39: 전문대 | O39: 계명문화대학 | P39: 멀티미디어 | Q39: 대구 | R39: 전문 | S39: 39122 | AE39: =(TRUNC(AD39/12))&"년 "&(ROUNDDOWN(MOD(AD39,12),0))&"개월" -> 0년 0개월 | AF39: =($AL$1-K39)/30 -> 59.5 | AG39: =(TRUNC(AF39/12))&"년 "&(ROUNDDOWN(MOD(AF39,12),0))&"개월" -> 4년 11개월 | AH39: =+AD39+AF39 -> 59.5 | AI39: =(TRUNC(AH39/12))&"년 "&(ROUNDDOWN(MOD(AH39,12),0))&"개월" -> 4년 11개월 | AJ39: 대구시 달서구 장기로 88 | AK39: 010-8235-1989 | AL39: hjjo@in-soft.co.kr | AN39: (양)86.01.16 | AO39: 01.16 | AQ39: 승인
A40: 112 | B40: 240402 | C40: 비개발 | D40: 김성희 | E40: 2 | F40: 사원 | H40: 경영지원본부 | I40: NIA사업팀 | J40: 891212-2673716 | K40: 45384 | N40: 일반대 | O40: 영남대학교 | P40: 서양화과 | Q40: 경북 경산 | R40: 학사 | S40: 40961 | AD40: 30.53 | AE40: =(TRUNC(AD40/12))&"년 "&(ROUNDDOWN(MOD(AD40,12),0))&"개월" -> 2년 6개월 | AF40: =(재직자!$AL$1-K40)/30 -> 24.333333 | AG40: =(TRUNC(AF40/12))&"년 "&(ROUNDDOWN(MOD(AF40,12),0))&"개월" -> 2년 0개월 | AH40: =+AD40+AF40 -> 54.863333 | AI40: =(TRUNC(AH40/12))&"년 "&(ROUNDDOWN(MOD(AH40,12),0))&"개월" -> 4년 6개월 | AJ40: 대구시 수성구 노변로 11 (노변대백맨션 103동 805호) | AK40: 010-5877-4077 | AL40: shkim@in-soft.co.kr | AN40: (양)89.12.12 | AQ40: 승인
...

Sheet Sheet1
C3: 천승무 | D3: (기타의견 : 프로젝트에서도 내부 인력끼리만 일하는 규모가 큰 프로젝트 보다 5명 전후의 프로젝트나 파견시 외부 고객과의 회의나 소통이 잦다고 판단되는데 주로 갑이 을을 바라볼 때 호칭이 명확한 것이 소통이 원할하다고 판단됩니다. 반면 갑의 입장에선 반대로 직무나 역할 분담의 호칭이 유리하다는 생각입니다.)
D5: 직급 체계와 관련하여 아래와 같은 직급 체계는 어떨까요?
D6: 일단 NIA 및 공공연기관 등과 같은 곳은 아래와 같은 직급 체계를 이용하더군요
D8: 그래서 먼저 말씀하신 제안 2가지 중에는 2안을 선택합니다.
C9: 최성현 | D9: 다만 추가로 제안을 한다면 아래와 같이 책임 직급을 책임 연구원과 선임 연구원으로 분류 하는 것이 어떨지요.
D10: ※ 참고로 NIA의 직급체계가 아래와 같습니다.
D12: 직금 계정(제안)
D13: 본부장
D14: 팀장
D15: 수석 연구원 | E15: 부장
D16: 책임 연구원 | E16: 차장
D17: 선임 연구원 | E17: 과장
D18: 주임 연구원 | E18: 대리
D19: 연구원 | E19: 사원
